[2022-04-20 01:02:06,948] {taskinstance.py:1043} INFO - Dependencies all met for <TaskInstance: fhv_taxi_data.local_to_gcs_task scheduled__2019-03-02T08:00:00+00:00 [queued]>
[2022-04-20 01:02:06,954] {taskinstance.py:1043} INFO - Dependencies all met for <TaskInstance: fhv_taxi_data.local_to_gcs_task scheduled__2019-03-02T08:00:00+00:00 [queued]>
[2022-04-20 01:02:06,954] {taskinstance.py:1249} INFO - 
--------------------------------------------------------------------------------
[2022-04-20 01:02:06,954] {taskinstance.py:1250} INFO - Starting attempt 1 of 2
[2022-04-20 01:02:06,954] {taskinstance.py:1251} INFO - 
--------------------------------------------------------------------------------
[2022-04-20 01:02:06,967] {taskinstance.py:1270} INFO - Executing <Task(PythonOperator): local_to_gcs_task> on 2019-03-02 08:00:00+00:00
[2022-04-20 01:02:06,970] {standard_task_runner.py:52} INFO - Started process 255 to run task
[2022-04-20 01:02:06,972] {standard_task_runner.py:79} INFO - Running: ['***', 'tasks', 'run', 'fhv_taxi_data', 'local_to_gcs_task', 'scheduled__2019-03-02T08:00:00+00:00', '--job-id', '21', '--raw', '--subdir', 'DAGS_FOLDER/data_ingestion_gcs_dag_v02.py', '--cfg-path', '/tmp/tmp9vwk42r3', '--error-file', '/tmp/tmpkg4qvoq4']
[2022-04-20 01:02:06,972] {standard_task_runner.py:80} INFO - Job 21: Subtask local_to_gcs_task
[2022-04-20 01:02:07,005] {logging_mixin.py:109} INFO - Running <TaskInstance: fhv_taxi_data.local_to_gcs_task scheduled__2019-03-02T08:00:00+00:00 [running]> on host 5e56b5a44db8
[2022-04-20 01:02:07,037] {warnings.py:110} WARNING - /home/***/.local/lib/python3.7/site-packages/***/utils/context.py:156: AirflowContextDeprecationWarning: Accessing 'execution_date' from the template is deprecated and will be removed in a future version. Please use 'data_interval_start' or 'logical_date' instead.
  warnings.warn(_create_deprecation_warning(key, self._deprecation_replacements[key]))

[2022-04-20 01:02:07,055] {taskinstance.py:1448} INFO - Exporting the following env vars:
AIRFLOW_CTX_DAG_OWNER=***
AIRFLOW_CTX_DAG_ID=fhv_taxi_data
AIRFLOW_CTX_TASK_ID=local_to_gcs_task
AIRFLOW_CTX_EXECUTION_DATE=2019-03-02T08:00:00+00:00
AIRFLOW_CTX_DAG_RUN_ID=scheduled__2019-03-02T08:00:00+00:00
[2022-04-20 01:02:19,119] {taskinstance.py:1774} ERROR - Task failed with exception
Traceback (most recent call last):
  File "/home/airflow/.local/lib/python3.7/site-packages/urllib3/connectionpool.py", line 710, in urlopen
    chunked=chunked,
  File "/home/airflow/.local/lib/python3.7/site-packages/urllib3/connectionpool.py", line 449, in _make_request
    six.raise_from(e, None)
  File "<string>", line 3, in raise_from
  File "/home/airflow/.local/lib/python3.7/site-packages/urllib3/connectionpool.py", line 444, in _make_request
    httplib_response = conn.getresponse()
  File "/usr/local/lib/python3.7/http/client.py", line 1373, in getresponse
    response.begin()
  File "/usr/local/lib/python3.7/http/client.py", line 319, in begin
    version, status, reason = self._read_status()
  File "/usr/local/lib/python3.7/http/client.py", line 288, in _read_status
    raise RemoteDisconnected("Remote end closed connection without"
http.client.RemoteDisconnected: Remote end closed connection without response

During handling of the above exception, another exception occurred:

Traceback (most recent call last):
  File "/home/airflow/.local/lib/python3.7/site-packages/requests/adapters.py", line 450, in send
    timeout=timeout
  File "/home/airflow/.local/lib/python3.7/site-packages/urllib3/connectionpool.py", line 786, in urlopen
    method, url, error=e, _pool=self, _stacktrace=sys.exc_info()[2]
  File "/home/airflow/.local/lib/python3.7/site-packages/urllib3/util/retry.py", line 550, in increment
    raise six.reraise(type(error), error, _stacktrace)
  File "/home/airflow/.local/lib/python3.7/site-packages/urllib3/packages/six.py", line 769, in reraise
    raise value.with_traceback(tb)
  File "/home/airflow/.local/lib/python3.7/site-packages/urllib3/connectionpool.py", line 710, in urlopen
    chunked=chunked,
  File "/home/airflow/.local/lib/python3.7/site-packages/urllib3/connectionpool.py", line 449, in _make_request
    six.raise_from(e, None)
  File "<string>", line 3, in raise_from
  File "/home/airflow/.local/lib/python3.7/site-packages/urllib3/connectionpool.py", line 444, in _make_request
    httplib_response = conn.getresponse()
  File "/usr/local/lib/python3.7/http/client.py", line 1373, in getresponse
    response.begin()
  File "/usr/local/lib/python3.7/http/client.py", line 319, in begin
    version, status, reason = self._read_status()
  File "/usr/local/lib/python3.7/http/client.py", line 288, in _read_status
    raise RemoteDisconnected("Remote end closed connection without"
urllib3.exceptions.ProtocolError: ('Connection aborted.', RemoteDisconnected('Remote end closed connection without response'))

During handling of the above exception, another exception occurred:

Traceback (most recent call last):
  File "/home/airflow/.local/lib/python3.7/site-packages/airflow/operators/python.py", line 174, in execute
    return_value = self.execute_callable()
  File "/home/airflow/.local/lib/python3.7/site-packages/airflow/operators/python.py", line 188, in execute_callable
    return self.python_callable(*self.op_args, **self.op_kwargs)
  File "/opt/airflow/dags/data_ingestion_gcs_dag_v02.py", line 48, in upload_to_gcs
    blob.upload_from_filename(local_file)
  File "/home/airflow/.local/lib/python3.7/site-packages/google/cloud/storage/blob.py", line 2735, in upload_from_filename
    retry=retry,
  File "/home/airflow/.local/lib/python3.7/site-packages/google/cloud/storage/blob.py", line 2594, in upload_from_file
    retry=retry,
  File "/home/airflow/.local/lib/python3.7/site-packages/google/cloud/storage/blob.py", line 2412, in _do_upload
    retry=retry,
  File "/home/airflow/.local/lib/python3.7/site-packages/google/cloud/storage/blob.py", line 2237, in _do_resumable_upload
    retry=retry,
  File "/home/airflow/.local/lib/python3.7/site-packages/google/cloud/storage/blob.py", line 2112, in _initiate_resumable_upload
    timeout=timeout,
  File "/home/airflow/.local/lib/python3.7/site-packages/google/resumable_media/requests/upload.py", line 421, in initiate
    retriable_request, self._get_status_code, self._retry_strategy
  File "/home/airflow/.local/lib/python3.7/site-packages/google/resumable_media/requests/_request_helpers.py", line 170, in wait_and_retry
    raise error
  File "/home/airflow/.local/lib/python3.7/site-packages/google/resumable_media/requests/_request_helpers.py", line 147, in wait_and_retry
    response = func()
  File "/home/airflow/.local/lib/python3.7/site-packages/google/resumable_media/requests/upload.py", line 413, in retriable_request
    method, url, data=payload, headers=headers, timeout=timeout
  File "/home/airflow/.local/lib/python3.7/site-packages/google/auth/transport/requests.py", line 486, in request
    **kwargs
  File "/home/airflow/.local/lib/python3.7/site-packages/requests/sessions.py", line 529, in request
    resp = self.send(prep, **send_kwargs)
  File "/home/airflow/.local/lib/python3.7/site-packages/requests/sessions.py", line 645, in send
    r = adapter.send(request, **kwargs)
  File "/home/airflow/.local/lib/python3.7/site-packages/requests/adapters.py", line 501, in send
    raise ConnectionError(err, request=request)
requests.exceptions.ConnectionError: ('Connection aborted.', RemoteDisconnected('Remote end closed connection without response'))
[2022-04-20 01:02:19,151] {taskinstance.py:1288} INFO - Marking task as UP_FOR_RETRY. dag_id=fhv_taxi_data, task_id=local_to_gcs_task, execution_date=20190302T080000, start_date=20220420T010206, end_date=20220420T010219
[2022-04-20 01:02:19,164] {standard_task_runner.py:98} ERROR - Failed to execute job 21 for task local_to_gcs_task (('Connection aborted.', RemoteDisconnected('Remote end closed connection without response')); 255)
[2022-04-20 01:02:19,192] {local_task_job.py:154} INFO - Task exited with return code 1
[2022-04-20 01:02:19,216] {local_task_job.py:264} INFO - 0 downstream tasks scheduled from follow-on schedule check
